Workbook
Name CAPM_EXPECTED_RETURN: LAMBDA(0.034 + Assets!$D$21*(0.085-0.034))
Name SlicerCache_Table_1_Col_1: #N/A

Sheet Assets
A1: Asset Name | B1: Expected Return (%) | C1: Volatility (%) | D1: Beta | E1: Weight (%) | F1: Investment | G1: Columna 7 | H1: CAPM Expected Return | I1: Variance | J1: Weights Squared
A2: Barclays | B2: 0.1252 | C2: 0.28 | D2: 1.2 | E2: =DIVIDE(F2,Summary!$D$22) -> 0.034708965 | F2: 550 | H2: 0.0952 | I2: =C2^2 -> 0.0784 | J2: =E2^2 -> 0.0012047123
A3: DHT | B3: 0.3773 | C3: 0.3638 | D3: 1.05 | E3: =DIVIDE(F3,Summary!$D$22) -> 0.055632161 | F3: 881.55 | H3: =0.034 + D3*(0.085-0.034) -> 0.08755 | I3: =C3^2 -> 0.13235044 | J3: =E3^2 -> 0.0030949373
A4: O (Realty Income Corp) | B4: 0.0929 | C4: 0.17 | D4: 1 | E4: =DIVIDE(F4,Summary!$D$22) -> 0.049982172 | F4: 792.02 | H4: =0.034 + D4*(0.085-0.034) -> 0.085 | I4: =C4^2 -> 0.0289 | J4: =E4^2 -> 0.0024982175
A5: Societe Generale (GLE.PA) | B5: 0.2727 | C5: 0.3624 | D5: 1.3 | E5: =DIVIDE(F5,Summary!$D$22) -> 0.053450544 | F5: 846.98 | H5: =0.034 + D5*(0.085-0.034) -> 0.1003 | I5: =C5^2 -> 0.13133376 | J5: =E5^2 -> 0.0028569607
A6: NWG.L | B6: 0.1391 | C6: 0.4323 | D6: 1.4 | E6: =DIVIDE(F6,Summary!$D$22) -> 0.027676929 | F6: 438.57 | H6: =0.034 + D6*(0.085-0.034) -> 0.1054 | I6: =C6^2 -> 0.18688329 | J6: =E6^2 -> 0.0007660124
A7: 03993.HK (China Molybdenum Company) | B7: 0.3776 | C7: 0.46 | D7: 1.33 | E7: =DIVIDE(F7,Summary!$D$22) -> 0.030075634 | F7: 476.58 | H7: =0.034 + D7*(0.085-0.034) -> 0.10183 | I7: =C7^2 -> 0.2116 | J7: =E7^2 -> 0.00090454376
A8: Acciona | B8: 0.256 | C8: 0.22 | D8: 0.73 | E8: =DIVIDE(F8,Summary!$D$22) -> 0.038433553 | F8: 609.02 | H8: =0.034 + D8*(0.085-0.034) -> 0.07123 | I8: =C8^2 -> 0.0484 | J8: =E8^2 -> 0.001477138
A9: Citigroup | B9: 0.1021 | C9: 0.33 | D9: 1.455 | E9: =DIVIDE(F9,Summary!$D$22) -> 0.023875982 | F9: 378.34 | H9: =0.034 + D9*(0.085-0.034) -> 0.108205 | I9: =C9^2 -> 0.1089 | J9: =E9^2 -> 0.0005700625
A10: Volkswagen | B10: 0.4819 | C10: 0.35 | D10: 1.32 | E10: =DIVIDE(F10,Summary!$D$22) -> 0.046908851 | F10: 743.32 | H10: =0.034 + D10*(0.085-0.034) -> 0.10132 | I10: =C10^2 -> 0.1225 | J10: =E10^2 -> 0.0022004403
A11: Merlin Properties | B11: 0.2558 | C11: 0.286 | D11: 0.6 | E11: =DIVIDE(F11,Summary!$D$22) -> 0.027993096 | F11: 443.58 | H11: =0.034 + D11*(0.085-0.034) -> 0.0646 | I11: =C11^2 -> 0.081796 | J11: =E11^2 -> 0.00078361343
A12: WBA | B12: 0.1222 | C12: 0.3428 | D12: 0.8 | E12: =DIVIDE(F12,Summary!$D$22) -> 0.073853736 | F12: 1170.29 | H12: =0.034 + D12*(0.085-0.034) -> 0.0748 | I12: =C12^2 -> 0.11751184 | J12: =E12^2 -> 0.0054543744
A13: BAC | B13: 0.0195 | C13: =(0.1944+0.194+0.1706)/3 -> 0.18633333 | D13: 1.3 | E13: =DIVIDE(F13,Summary!$D$22) -> 0.018970027 | F13: 300.6 | H13: =0.034 + D13*(0.085-0.034) -> 0.1003 | I13: =C13^2 -> 0.034720111 | J13: =E13^2 -> 0.00035986193
A14: BNS | B14: 0.003 | C14: 0.2682 | D14: 0.9 | E14: =DIVIDE(F14,Summary!$D$22) -> 0.026113763 | F14: 413.8 | H14: =0.034 + D14*(0.085-0.034) -> 0.0799 | I14: =C14^2 -> 0.07193124 | J14: =E14^2 -> 0.00068192864
A15: 2899.hk (Zijin Mining Group) | B15: 0.3896 | C15: 0.3833 | D15: 1.52 | E15: =DIVIDE(F15,Summary!$D$22) -> 0.023532678 | F15: 372.9 | H15: =0.034 + D15*(0.085-0.034) -> 0.11152 | I15: =C15^2 -> 0.14691889 | J15: =E15^2 -> 0.00055378696
A16: T | B16: -0.0076 | C16: 0.3054 | D16: 0.6 | E16: =DIVIDE(F16,Summary!$D$22) -> 0.015635442 | F16: 247.76 | H16: =0.034 + D16*(0.085-0.034) -> 0.0646 | I16: =C16^2 -> 0.09326916 | J16: =E16^2 -> 0.00024446705
A17: BMO | B17: 0.0186 | C17: 0.2125 | D17: 1.04 | E17: =DIVIDE(F17,Summary!$D$22) -> 0.019052067 | F17: 301.9 | H17: =0.034 + D17*(0.085-0.034) -> 0.08704 | I17: =C17^2 -> 0.04515625 | J17: =E17^2 -> 0.00036298124
A18: ENB | B18: -0.0054 | C18: 0.1677 | D18: 0.94 | E18: =DIVIDE(F18,Summary!$D$22) -> 0.016883703 | F18: 267.54 | H18: =0.034 + D18*(0.085-0.034) -> 0.08194 | I18: =C18^2 -> 0.02812329 | J18: =E18^2 -> 0.00028505942
A19: GILD | B19: 0.0649 | C19: 0.2991 | D19: 0.82 | E19: =DIVIDE(F19,Summary!$D$22) -> 0.014759514 | F19: 233.88 | H19: =0.034 + D19*(0.085-0.034) -> 0.07582 | I19: =C19^2 -> 0.08946081 | J19: =E19^2 -> 0.00021784326
A20: IRS (Argentinian IRSA) | B20: -0.1243 | C20: 0.4502 | D20: 1.27 | E20: =DIVIDE(F20,Summary!$D$22) -> 0.0091076325 | F20: 144.32 | H20: =0.034 + D20*(0.085-0.034) -> 0.09877 | I20: =C20^2 -> 0.20268004 | J20: =E20^2 -> 8.294897e-05
A21: TLT (iShares 20+ Year Treasuries ETF) | B21: -0.0078 | C21: 0.1659 | D21: 0.22 | E21: =DIVIDE(F21,Summary!$D$22) -> 0.018301091 | F21: 290 | H21: =0.034 + D21*(0.085-0.034) -> 0.04522 | I21: =C21^2 -> 0.02752281 | J21: =E21^2 -> 0.00033492992
A22: Mapfre (MAP.MC) | B22: 0.0634 | C22: 0.2764 | D22: 1.17 | E22: =DIVIDE(F22,Summary!$D$22) -> 0.014218054 | F22: 225.3 | H22: =0.034 + D22*(0.085-0.034) -> 0.09367 | I22: =C22^2 -> 0.07639696 | J22: =E22^2 -> 0.00020215307
A23: DOCS.L (Dr. Hopkins) | B23: 0.0948 | C23: 0.3792 | D23: 0.97 | E23: =DIVIDE(F23,Summary!$D$22) -> 0.014272958 | F23: 226.17 | H23: =0.034 + D23*(0.085-0.034) -> 0.08347 | I23: =C23^2 -> 0.14379264 | J23: =E23^2 -> 0.00020371732
A24: Vodafone (US) | B24: 0.3068 | C24: 0.2849 | D24: 0.72 | E24: =DIVIDE(F24,Summary!$D$22) -> 0.015671413 | F24: 248.33 | H24: =0.034 + D24*(0.085-0.034) -> 0.07072 | I24: =C24^2 -> 0.08116801 | J24: =E24^2 -> 0.0002455932
A25: SDGR | B25: 0.4311 | C25: 0.4173 | D25: 1.36 | E25: =DIVIDE(F25,Summary!$D$22) -> 0.012983677 | F25: 205.74 | H25: =0.034 + D25*(0.085-0.034) -> 0.10336 | I25: =C25^2 -> 0.17413929 | J25: =E25^2 -> 0.00016857588
... A42: Pfizer | B42: 0.2327 | C42: 0.0761 | D42: 0.67 | E42: =DIVIDE(F42,Summary!$D$22) -> 0.0094660815 | F42: 150 | H42: =0.034 + D42*(0.085-0.034) -> 0.06817 | I42: =C42^2 -> 0.00579121 | J42: =E42^2 -> 8.9606698e-05
A43: Telefonica (Spanish stock exchange) | B43: -0.0018 | C43: 0.19625 | D43: =(0.67+0.68+0.68)/3 -> 0.67666667 | E43: =DIVIDE(F43,Summary!$D$22) -> 0.0069424241 | F43: 110.01 | H43: =0.034 + D43*(0.085-0.034) -> 0.06851 | I43: =C43^2 -> 0.038514063 | J43: =E43^2 -> 4.8197253e-05
A44: LYG (Lloyd's Banking) | B44: 0.2378 | C44: =(0.192+0.255+0.289)/3 -> 0.24533333 | D44: 1.24 | E44: =DIVIDE(F44,Summary!$D$22) -> 0.006310721 | F44: 100 | H44: =0.034 + D44*(0.085-0.034) -> 0.09724 | I44: =C44^2 -> 0.060188444 | J44: =E44^2 -> 3.9825199e-05
A45: SDR.L (Schroders) | B45: 0.1628 | C45: 0.072 | D45: 1.09 | E45: =DIVIDE(F45,Summary!$D$22) -> 0.0088356404 | F45: 140.01 | H45: =0.034 + D45*(0.085-0.034) -> 0.08959 | I45: =C45^2 -> 0.005184 | J45: =E45^2 -> 7.8068542e-05
A46: SHEL Plc ADR | B46: 0.2767 | C46: 0.0654 | D46: 0.66 | E46: =DIVIDE(F46,Summary!$D$22) -> 0.00814083 | F46: 129 | H46: =0.034 + D46*(0.085-0.034) -> 0.06766 | I46: =C46^2 -> 0.00427716 | J46: =E46^2 -> 6.6273114e-05
A47: ISP.MI (Intesa Sanpaolo) | B47: 0.2597 | C47: 0.0558 | D47: 1.32 | E47: =DIVIDE(F47,Summary!$D$22) -> 0.006310721 | F47: 100 | H47: =0.034 + D47*(0.085-0.034) -> 0.10132 | I47: =C47^2 -> 0.00311364 | J47: =E47^2 -> 3.9825199e-05
A48: OXY | B48: 0.2587 | C48: 0.1327 | D48: 1.47 | E48: =DIVIDE(F48,Summary!$D$22) -> 0.0068793169 | F48: 109.01 | H48: =0.034 + D48*(0.085-0.034) -> 0.10897 | I48: =C48^2 -> 0.01760929 | J48: =E48^2 -> 4.7325001e-05
A49: P911.DE | B49: 0.3962 | C49: 0.2809 | D49: 1.21 | E49: =DIVIDE(F49,Summary!$D$22) -> 0.0078814594 | F49: 124.89 | H49: =0.034 + D49*(0.085-0.034) -> 0.09571 | I49: =C49^2 -> 0.07890481 | J49: =E49^2 -> 6.2117403e-05
A50: RIO | B50: 0.3166 | C50: 0.3245 | D50: 0.59 | E50: =DIVIDE(F50,Summary!$D$22) -> 0.0068786859 | F50: 109 | H50: =0.034 + D50*(0.085-0.034) -> 0.06409 | I50: =C50^2 -> 0.10530025 | J50: =E50^2 -> 4.7316319e-05
A51: KHC | B51: 0.1399 | C51: 0.0145 | D51: 0.76 | E51: =DIVIDE(F51,Summary!$D$22) -> 0.0062785363 | F51: 99.49 | H51: =0.034 + D51*(0.085-0.034) -> 0.07276 | I51: =C51^2 -> 0.00021025 | J51: =E51^2 -> 3.9420018e-05
A52: AGG (iShares Core US Aggregate Bond ETF) | B52: -0.0423 | C52: 0.0615 | D52: 0.07 | E52: =DIVIDE(F52,Summary!$D$22) -> 0.0063063035 | F52: 99.93 | H52: =0.034 + D52*(0.085-0.034) -> 0.03757 | I52: =C52^2 -> 0.00378225 | J52: =E52^2 -> 3.9769463e-05
A53: Akzo Nobel (AKZA.NV) | B53: 0.3201 | C53: 0.2825 | D53: 1.1 | E53: =DIVIDE(F53,Summary!$D$22) -> 0.006626257 | F53: 105 | H53: =0.034 + D53*(0.085-0.034) -> 0.0901 | I53: =C53^2 -> 0.07980625 | J53: =E53^2 -> 4.3907282e-05
A54: PAAS | B54: 0.3373 | C54: 0.434 | D54: 1.19 | E54: =DIVIDE(F54,Summary!$D$22) -> 0.0055597452 | F54: 88.1 | H54: =0.034 + D54*(0.085-0.034) -> 0.09469 | I54: =C54^2 -> 0.188356 | J54: =E54^2 -> 3.0910766e-05
A55: DB | B55: 0.1899 | C55: 0.382 | D55: 1.52 | E55: =DIVIDE(F55,Summary!$D$22) -> 0.0031553605 | F55: 50 | H55: =0.034 + D55*(0.085-0.034) -> 0.11152 | I55: =C55^2 -> 0.145924 | J55: =E55^2 -> 9.9562998e-06
A56: PDM | B56: 0.1405 | C56: 0.288 | D56: 1.21 | E56: =DIVIDE(F56,Summary!$D$22) -> 0.0026025413 | F56: 41.24 | H56: =0.034 + D56*(0.085-0.034) -> 0.09571 | I56: =C56^2 -> 0.082944 | J56: =E56^2 -> 6.7732214e-06
...

Sheet Summary
A1: Metric | D1: Value | L1: Comparison of CAPM vs Analysts (Tradingview) | P1: Portfolio VARIANCE | R1: Portfolio SD / Volatility
L2: Explicación: el dato del retorno esperado del mercado (Rm)utilizado ha sido 8,5% y el risk-free rate 3,4%. Al haber infraestimado un poco los valores (son estimaciones verídicas de datos factuales y predicciones reales para 2025, pero las hay más altas también), podría entenderse que las predicciones de los analistas fueran más altas. Por tanto, creamos esta columna de comparaciónes para ver anomalías, que sería el caso donde CAPM estime más retorno que los analistas. Estas empresas "anómalas" podrían tener algún tipo de problema en el futuro y se aconseja incluso desinvertir parcialmente. | M2: #anomalies = | N2: =COUNTIF(L10:L63, "CAPM>TradingviewAnalyst") -> 14 | O2: Case A: if they weren't correlated (this formula assumes Pearson's correlation coefficient 𝛒 is 0). That's why it is so low | P2: =SUMPRODUCT(Assets!I2:I62,Assets!J2:J62) -> 0.0031374264 | R2: =SQRT(P2) -> 0.056012734
A3: Portfolio Expected Return (%) | D3: =(SUMPRODUCT(Assets!B2:B62,Assets!E2:E62))*100 -> 39.976024 | L3: =IF(Assets!B2>Assets!H2, "TradingviewAnalyst>CAPM", "CAPM>TradingviewAnalyst") -> TradingviewAnalyst>CAPM
A4: Portfolio Risk (Volatility %) | D4: =SQRT(P4) -> 0.18036641 | L4: =IF(Assets!B3>Assets!H3, "TradingviewAnalyst>CAPM", "CAPM>TradingviewAnalyst") -> TradingviewAnalyst>CAPM | O4: Case B: admitting the obvious correlations (assuming a 30% average correlation, which is actually rounding it up and nearly only happens at high-volatility times like crises or crashes), and using the factorial for the 62 assets [ 62! / (60! * 2!) ] , which is 1891. In any case, this is not super exact due to having assumed the Pearson coefficient and having used average weights instead of actually associating each Pearson to each weight (higher or lower). Therefore, the real variance of the portfolio could vary from this. | P4: =P2+(2*E20*D17^2)*1891 -> 0.032532041 | R4: =SQRT(P4) -> 0.18036641
A5: Portfolio Beta | D5: =SUMPRODUCT(Assets!D2:D62,Assets!E2:E62) -> 1.021451 | E5: (Weighted average Beta) | L5: =IF(Assets!B4>Assets!H4, "TradingviewAnalyst>CAPM", "CAPM>TradingviewAnalyst") -> TradingviewAnalyst>CAPM
A6: Sharpe Ratio | D6: =(D3/100 - 0.034) / D4 -> 2.0278734 | L6: =IF(Assets!B5>Assets!H5, "TradingviewAnalyst>CAPM", "CAPM>TradingviewAnalyst") -> TradingviewAnalyst>CAPM
L7: =IF(Assets!B6>Assets!H6, "TradingviewAnalyst>CAPM", "CAPM>TradingviewAnalyst") -> TradingviewAnalyst>CAPM
L8: =IF(Assets!B7>Assets!H7, "TradingviewAnalyst>CAPM", "CAPM>TradingviewAnalyst") -> TradingviewAnalyst>CAPM
A9: Unweighted average E(r) | D9: =AVERAGE(Assets!B2:B62) -> 0.57688525 | L9: =IF(Assets!B8>Assets!H8, "TradingviewAnalyst>CAPM", "CAPM>TradingviewAnalyst") -> TradingviewAnalyst>CAPM
A10: Unweighted average VOL | D10: =AVERAGE(Assets!C2:C62) -> 0.30844536 | L10: =IF(Assets!B9>Assets!H9, "TradingviewAnalyst>CAPM", "CAPM>TradingviewAnalyst") -> CAPM>TradingviewAnalyst
A11: Weighted average VOLATILITY | D11: =SUMPRODUCT(Tabla_1[[#DATA],[#TOTALS],[Volatility (%)]],Tabla_1[[#DATA],[#TOTALS],[Weight (%)]]) -> 0.31048622 | L11: =IF(Assets!B10>Assets!H10, "TradingviewAnalyst>CAPM", "CAPM>TradingviewAnalyst") -> TradingviewAnalyst>CAPM
L12: =IF(Assets!B11>Assets!H11, "TradingviewAnalyst>CAPM", "CAPM>TradingviewAnalyst") -> TradingviewAnalyst>CAPM
L13: =IF(Assets!B12>Assets!H12, "TradingviewAnalyst>CAPM", "CAPM>TradingviewAnalyst") -> TradingviewAnalyst>CAPM
L14: =IF(Assets!B13>Assets!H13, "TradingviewAnalyst>CAPM", "CAPM>TradingviewAnalyst") -> CAPM>TradingviewAnalyst
B15: Average CAPM E(r) ---> | C15: =(0.034+D11*(0.085-0.034))*100 -> 4.9834797 | D15: % | H15: Total annualized profit (as of 01/12/24) = | I15: =((1+G25/100)^(1/(2+2/3))-1)*100 -> 8.9097977 | J15: % | L15: =IF(Assets!B14>Assets!H14, "TradingviewAnalyst>CAPM", "CAPM>TradingviewAnalyst") -> CAPM>TradingviewAnalyst
L16: =IF(Assets!B15>Assets!H15, "TradingviewAnalyst>CAPM", "CAPM>TradingviewAnalyst") -> TradingviewAnalyst>CAPM
A17: Average asset weight | D17: =AVERAGE(Assets!E2:E63) -> 0.016393443 | L17: =IF(Assets!B16>Assets!H16, "TradingviewAnalyst>CAPM", "CAPM>TradingviewAnalyst") -> CAPM>TradingviewAnalyst
A18: Average investment/asset | D18: =AVERAGE(Assets!F2:F62) -> 259.77131 | L18: =IF(Assets!B17>Assets!H17, "TradingviewAnalyst>CAPM", "CAPM>TradingviewAnalyst") -> CAPM>TradingviewAnalyst
A19: Average Beta (unweighted) | D19: =AVERAGE(Assets!D2:D62) -> 1.0055027 | L19: =IF(Assets!B18>Assets!H18, "TradingviewAnalyst>CAPM", "CAPM>TradingviewAnalyst") -> CAPM>TradingviewAnalyst
A20: Average asset COVARIANCE (𝛒*𝛔1*𝛔2)= | E20: =0.3 * D11^2 -> 0.028920508 | L20: =IF(Assets!B19>Assets!H19, "TradingviewAnalyst>CAPM", "CAPM>TradingviewAnalyst") -> CAPM>TradingviewAnalyst
A21: supposing a 30% Pearson's correlation coefficient | L21: =IF(Assets!B20>Assets!H20, "TradingviewAnalyst>CAPM", "CAPM>TradingviewAnalyst") -> CAPM>TradingviewAnalyst
A22: Total invested= | D22: =SUM(Assets!F2:F63) -> 15846.05 | L22: =IF(Assets!B21>Assets!H21, "TradingviewAnalyst>CAPM", "CAPM>TradingviewAnalyst") -> CAPM>TradingviewAnalyst
A23: CV (as of 01/12/2024) = | D23: 17334.57 | L23: =IF(Assets!B22>Assets!H22, "TradingviewAnalyst>CAPM", "CAPM>TradingviewAnalyst") -> CAPM>TradingviewAnalyst
A24: Carrying profit (%) = | D24: =((D23/D22)-1)*100 -> 9.3936344 | L24: =IF(Assets!B23>Assets!H23, "TradingviewAnalyst>CAPM", "CAPM>TradingviewAnalyst") -> TradingviewAnalyst>CAPM
A25: Total profit (considering an exchange rate of 1,062) (%) = | G25: =((D23/(13000*1.062))-1)*100 -> 25.558236 | L25: =IF(Assets!B24>Assets!H24, "TradingviewAnalyst>CAPM", "CAPM>TradingviewAnalyst") -> TradingviewAnalyst>CAPM
L26: =IF(Assets!B25>Assets!H25, "TradingviewAnalyst>CAPM", "CAPM>TradingviewAnalyst") -> TradingviewAnalyst>CAPM
L27: =IF(Assets!B26>Assets!H26, "TradingviewAnalyst>CAPM", "CAPM>TradingviewAnalyst") -> TradingviewAnalyst>CAPM
A28: Actual return for 2025 (*December 2024 included*) = | L28: =IF(Assets!B27>Assets!H27, "TradingviewAnalyst>CAPM", "CAPM>TradingviewAnalyst") -> TradingviewAnalyst>CAPM
L29: =IF(Assets!B28>Assets!H28, "TradingviewAnalyst>CAPM", "CAPM>TradingviewAnalyst") -> CAPM>TradingviewAnalyst
L30: =IF(Assets!B29>Assets!H29, "TradingviewAnalyst>CAPM", "CAPM>TradingviewAnalyst") -> TradingviewAnalyst>CAPM
L31: =IF(Assets!B30>Assets!H30, "TradingviewAnalyst>CAPM", "CAPM>TradingviewAnalyst") -> TradingviewAnalyst>CAPM
L32: =IF(Assets!B31>Assets!H31, "TradingviewAnalyst>CAPM", "CAPM>TradingviewAnalyst") -> TradingviewAnalyst>CAPM
L33: =IF(Assets!B32>Assets!H32, "TradingviewAnalyst>CAPM", "CAPM>TradingviewAnalyst") -> TradingviewAnalyst>CAPM
L34: =IF(Assets!B33>Assets!H33, "TradingviewAnalyst>CAPM", "CAPM>TradingviewAnalyst") -> TradingviewAnalyst>CAPM
L35: =IF(Assets!B34>Assets!H34, "TradingviewAnalyst>CAPM", "CAPM>TradingviewAnalyst") -> CAPM>TradingviewAnalyst
L36: =IF(Assets!B35>Assets!H35, "TradingviewAnalyst>CAPM", "CAPM>TradingviewAnalyst") -> TradingviewAnalyst>CAPM
L37: =IF(Assets!B36>Assets!H36, "TradingviewAnalyst>CAPM", "CAPM>TradingviewAnalyst") -> TradingviewAnalyst>CAPM
L38: =IF(Assets!B37>Assets!H37, "TradingviewAnalyst>CAPM", "CAPM>TradingviewAnalyst") -> TradingviewAnalyst>CAPM
L39: =IF(Assets!B38>Assets!H38, "TradingviewAnalyst>CAPM", "CAPM>TradingviewAnalyst") -> TradingviewAnalyst>CAPM
L40: =IF(Assets!B39>Assets!H39, "TradingviewAnalyst>CAPM", "CAPM>TradingviewAnalyst") -> TradingviewAnalyst>CAPM
...

Sheet Analysis
A1: DYNAMIC | B1: analysis
